# 九、异步编程

## 9.1 什么是 Promise

由于JS是单线程的，遇到耗时任务时，为防止代码阻塞，都需要异步处理该任务。比如ajax网络请求，定时器…

**传统解决方式: 回调函数**

```js
console.log('start');
setTimeout(function(){
    console.log('hello bf!!!')
},0)
console.log('end');
// 定时器就是一个需要异步处理的任务,我们以回调函数的形式,指定计时完成后要做的事情
// 文档的事件操作,也都是这样的处理方式
```

**Promise解决方式**

Promise 是异步编程的一种解决方案，比传统的解决方案——回调函数和事件——更合理和更强大。它由社区最早提出和实现，ES6 将其写进了语言标准，统一了用法，原生提供了`Promise`对象。

所谓`Promise`，简单说就是一个容器，里面保存着某个未来才会结束的事件（通常是一个异步操作）的结果。从语法上说，Promise 是一个对象，从它可以获取异步操作的消息。Promise 提供统一的 API，各种异步操作都可以用同样的方法进行处理。

有了`Promise`对象，就可以将异步操作以同步操作的流程表达出来，避免了层层嵌套的回调函数。此外，`Promise`对象提供统一的接口，使得控制异步操作更加容易。

### 基本用法

创建promise实例

ES6 规定，`Promise`对象是一个构造函数，用来生成`Promise`实例。

```javascript
var p = new Promise((resolve,reject)=>{
    setTimeout(()=>{
        var num=Math.ceil(Math.random()*10);
        if(num>5){
            resolve(num);
        }else{
            reject(num);
        }
    },500)
})
```

`Promise`构造函数接受一个函数作为参数，该函数的两个参数分别是`resolve`和`reject`。由 JavaScript 引擎提供。

`resolve`函数的作用是，将`Promise`对象的状态从“未完成”变为“成功”（即从 pending 变为 resolved），在异步操作成功时调用，并将异步操作的结果，作为参数传递出去；`reject`函数的作用是，将`Promise`对象的状态从“未完成”变为“失败”（即从 pending 变为 rejected），在异步操作失败时调用，并将异步操作报出的错误，作为参数传递出去。

### then()方法

`Promise`实例生成以后，可以用`then`方法分别指定当`promise`实例变为`resolved`状态和`rejected`状态的回调函数。

`then`方法可以接受两个回调函数作为参数。第一个回调函数是`Promise`对象的状态变为`resolved`时调用，第二个回调函数是`Promise`对象的状态变为`rejected`时调用。这两个函数都是可选的，不一定要提供。它们都接受`Promise`对象传出的值作为参数

```javascript
//处理结果的第一种方式
//处理结果
p.then(function(res){
    console.log("res",res);
},function(err){
    console.log("err",err);
})

//写成箭头函数会更加简便

p.then(res=>{
    console.log("res",res);
},err=>{
    console.log("err",err);
})
```



### catch()方法

`Promise.prototype.catch()`方法是`.then(null, rejection)`或`.then(undefined, rejection)`的别名，用于指定发生错误时的回调函数。

如果该对象状态变为`resolved`，则会调用`then()`方法指定的回调函数；如果异步操作抛出错误，状态就会变为`rejected`，就会调用`catch()`方法指定的回调函数，处理这个错误。另外，`then()`方法指定的回调函数，如果运行中抛出错误，也会被`catch()`方法捕获。

```javascript
//处理结果的第2种方式
p.then(res=>{
    console.log("res",res);
}).catch(err=>{
    console.log("err",err);
})
```

如果 Promise 状态已经变成`resolved`，再抛出错误是无效的。Promise 在`resolve`语句后面，再抛出错误，不会被捕获，等于没有抛出。因为 Promise 的状态一旦改变，就永久保持该状态，不会再变了。

Promise 对象的错误具有“冒泡”性质，会一直向后传递，直到被捕获为止。也就是说，错误总是会被下一个`catch`语句捕获。一般来说，不要在`then()`方法里面定义 Reject 状态的回调函数（即`then`的第二个参数），上面代码中，第二种写法要好于第一种写法，理由是第二种写法可以捕获前面`then`方法执行中的错误，也更接近同步的写法（`try/catch`）。 **推荐使用`catch`方法。**

### Promise 新建后就会立即执行

Promise 新建后立即执行，所以首先输出的是`Promise`。然后，`then`方法指定的回调函数，将在当前脚本所有同步任务执行完才会执行，所以`resolved`最后输出。



### `Promise`对象有以下两个特点

1. 对象的状态不受外界影响。`Promise`对象代表一个异步操作，**有三种状态：**`pending`（进行中）、`fulfilled`（已成功）和`rejected`（已失败）。只有异步操作的结果，可以决定当前是哪一种状态，任何其他操作都无法改变这个状态。这也是`Promise`这个名字的由来，它的英语意思就是“承诺”，表示其他手段无法改变。
2. 一旦状态改变，就不会再变，任何时候都可以得到这个结果。`Promise`对象的状态改变，只有两种可能：从`pending`变为`fulfilled`和从`pending`变为`rejected`。只要这两种情况发生，状态就凝固了，不会再变了，会一直保持这个结果，这时就称为 resolved（已定型）。如果改变已经发生了，你再对`Promise`对象添加回调函数，也会立即得到这个结果。这与事件（Event）完全不同，事件的特点是，如果你错过了它，再去监听，是得不到结果的。

`Promise`也**有一些缺点**。**首先**，无法取消`Promise`，一旦新建它就会立即执行，无法中途取消。**其次**，如果不设置回调函数，`Promise`内部抛出的错误，不会反应到外部。**第三**，当处于`pending`状态时，无法得知目前进展到哪一个阶段（刚刚开始还是即将完成）。

有了`Promise`对象，就可以将异步操作以同步操作的流程表达出来，避免了层层嵌套的回调函数。此外，`Promise`对象提供统一的接口，使得控制异步操作更加容易。

## 9.2 promise的链式编程

Promise 实例具有`then`方法，也就是说，`then`方法是定义在原型对象`Promise.prototype`上的。它的作用是为 Promise 实例添加状态改变时的回调函数。前面说过，`then`方法的第一个参数是`resolved`状态的回调函数，第二个参数是`rejected`状态的回调函数，它们都是可选的。

`then`方法返回的是一个新的`Promise`实例（注意，不是原来那个`Promise`实例）。因此可以采用链式写法，即`then`方法后面再调用另一个`then`方法。



上面代码中，第一个`then`方法指定的回调函数，返回的是另一个`Promise`对象。这时，第二个`then`方法指定的回调函数，就会等待这个新的`Promise`对象状态发生变化。如果变为`resolved`，就调用第一个回调函数，如果状态变为`rejected`，就调用第二个回调函数。

```javascript
var status = 1,isLogin=false;
var login = (resolve , reject)=>{
    setTimeout(()=>{
        if(status == 1){
            isLogin = true
            resolve({
                code : 1,
                token:"ad31nu891nv",
                msg:"登陆成功!"
            })
        }else{
            isLogin = false
            reject("失败")
        }
    },2000)
};
var getInfo = (resolve , reject)=>{
    setTimeout(()=>{
        if(isLogin){
            resolve("获取用户信息成功!")
        }else{
            reject("获取失败")
        }
    },1000)
};
new Promise(login)
.then(res =>{
    console.log(res);
    return new Promise(getInfo);
})
.then(res =>{
    console.log(res);
}).catch(err=>{
    console.log(err);
})
```

## 9.3 promise的其他属性



|                        |                                                          |      |
| ---------------------- | -------------------------------------------------------- | ---- |
| Promise.all()          | 用于将多个 Promise 实例，包装成一个新的 Promise 实例。   |      |
| Promise.race()         | 同样是将多个 Promise 实例，包装成一个新的 Promise 实例。 |      |
| Promise.resolve()      | 有时需要将现有对象转为 Promise 对象                      |      |
| Promise.reject(reason) | 返回一个新的 Promise 实例，该实例的状态为`rejected`。    |      |

> setTimout中传入的回调方法应该是被js引擎直接调用的，而引擎直接发出的报错，这可能就是捕获不到throw的原因。

## 10.1 什么是 Generator 函数

Generator 函数是 ES6 提供的一种异步编程解决方案，语法行为与传统函数完全不同。

Generator 函数有多种理解角度。语法上，首先可以把它理解成，Generator 函数是一个状态机，封装了多个内部状态。

执行 Generator 函数会返回一个遍历器对象，也就是说，Generator 函数除了状态机，还是一个遍历器对象生成函数。返回的遍历器对象，可以依次遍历 Generator 函数内部的每一个状态。

形式上，Generator 函数是一个普通函数，但是有两个特征。一是，`function`关键字与函数名之间有一个星号；二是，函数体内部使用`yield`表达式，定义不同的内部状态（`yield`在英语里的意思就是“产出”）。

```
function* helloWorldGenerator() {
  yield 'hello';
  yield 'world';
  return 'ending';
}

var hw = helloWorldGenerator();
```

上面代码定义了一个 Generator 函数`helloWorldGenerator`，它内部有两个`yield`表达式（`hello`和`world`），即该函数有三个状态：hello，world 和 return 语句（结束执行）。



然后，Generator 函数的调用方法与普通函数一样，也是在函数名后面加上一对圆括号。不同的是，调用 Generator 函数后，该函数并不执行，返回的也不是函数运行结果，而是一个指向内部状态的指针对象，也就是的遍历器对象（Iterator Object）。

下一步，必须调用遍历器对象的`next`方法，使得指针移向下一个状态。也就是说，每次调用`next`方法，内部指针就从函数头部或上一次停下来的地方开始执行，直到遇到下一个`yield`表达式（或`return`语句）为止。换言之，Generator 函数是分段执行的，`yield`表达式是暂停执行的标记，而`next`方法可以恢复执行。

```
hw.next()
// { value: 'hello', done: false }

hw.next()
// { value: 'world', done: false }

hw.next()
// { value: 'ending', done: true }

hw.next()
// { value: undefined, done: true }
```

上面代码一共调用了四次`next`方法。

第一次调用，Generator 函数开始执行，直到遇到第一个`yield`表达式为止。`next`方法返回一个对象，它的`value`属性就是当前`yield`表达式的值`hello`，`done`属性的值`false`，表示遍历还没有结束。

第二次调用，Generator 函数从上次`yield`表达式停下的地方，一直执行到下一个`yield`表达式。`next`方法返回的对象的`value`属性就是当前`yield`表达式的值`world`，`done`属性的值`false`，表示遍历还没有结束。

第三次调用，Generator 函数从上次`yield`表达式停下的地方，一直执行到`return`语句（如果没有`return`语句，就执行到函数结束）。`next`方法返回的对象的`value`属性，就是紧跟在`return`语句后面的表达式的值（如果没有`return`语句，则`value`属性的值为`undefined`），`done`属性的值`true`，表示遍历已经结束。

第四次调用，此时 Generator 函数已经运行完毕，`next`方法返回对象的`value`属性为`undefined`，`done`属性为`true`。以后再调用`next`方法，返回的都是这个值。

总结一下，调用 Generator 函数，返回一个遍历器对象，代表 Generator 函数的内部指针。以后，每次调用遍历器对象的`next`方法，就会返回一个有着`value`和`done`两个属性的对象。`value`属性表示当前的内部状态的值，是`yield`表达式后面那个表达式的值；`done`属性是一个布尔值，表示是否遍历结束。



### yield 表达式

由于 Generator 函数返回的遍历器对象，只有调用`next`方法才会遍历下一个内部状态，所以其实提供了一种可以暂停执行的函数。`yield`表达式就是暂停标志。

遍历器对象的`next`方法的运行逻辑如下。

（1）遇到`yield`表达式，就暂停执行后面的操作，并将紧跟在`yield`后面的那个表达式的值，作为返回的对象的`value`属性值。

（2）下一次调用`next`方法时，再继续往下执行，直到遇到下一个`yield`表达式。

（3）如果没有再遇到新的`yield`表达式，就一直运行到函数结束，直到`return`语句为止，并将`return`语句后面的表达式的值，作为返回的对象的`value`属性值。

（4）如果该函数没有`return`语句，则返回的对象的`value`属性值为`undefined`。



`yield`表达式与`return`语句既有相似之处，也有区别。相似之处在于，都能返回紧跟在语句后面的那个表达式的值。区别在于每次遇到`yield`，函数暂停执行，下一次再从该位置继续向后执行，而`return`语句不具备位置记忆的功能。一个函数里面，只能执行一次（或者说一个）`return`语句，但是可以执行多次（或者说多个）`yield`表达式。正常函数只能返回一个值，因为只能执行一次`return`；Generator 函数可以返回一系列的值，因为可以有任意多个`yield`。从另一个角度看，也可以说 Generator 生成了一系列的值，这也就是它的名称的来历（英语中，generator 这个词是“生成器”的意思）。


`yield`表达式只能用在 Generator 函数里面，用在其他地方都会报错。

`yield`表达式如果用在另一个表达式之中，必须放在圆括号里面。

`yield`表达式用作函数参数或放在赋值表达式的右边，可以不加括号。



### 与 Iterator 接口的关系

任意一个对象的`Symbol.iterator`方法，等于该对象的遍历器生成函数，调用该函数会返回该对象的一个遍历器对象。

由于 Generator 函数就是遍历器生成函数，因此可以把 Generator 赋值给对象的`Symbol.iterator`属性，从而使得该对象具有 Iterator 接口。

```
var myIterable = {};
myIterable[Symbol.iterator] = function* () {
  yield 1;
  yield 2;
  yield 3;
};

[...myIterable] // [1, 2, 3]
```

上面代码中，Generator 函数赋值给`Symbol.iterator`属性，从而使得`myIterable`对象具有了 Iterator 接口，可以被`...`运算符遍历了。

Generator 函数执行后，返回一个遍历器对象。该对象本身也具有`Symbol.iterator`属性，执行后返回自身。

```
function* gen(){
  // some code
}

var g = gen();

g[Symbol.iterator]() === g
// true
```

上面代码中，`gen`是一个 Generator 函数，调用它会生成一个遍历器对象`g`。它的`Symbol.iterator`属性，也是一个遍历器对象生成函数，执行后返回它自己。



### Generator.prototype.throw()

Generator 函数返回的遍历器对象，都有一个`throw`方法，可以在函数体外抛出错误，然后在 Generator 函数体内捕获。



`throw`方法可以接受一个参数，该参数会被`catch`语句接收，建议抛出`Error`对象的实例。



注意，不要混淆遍历器对象的`throw`方法和全局的`throw`命令。上面代码的错误，是用遍历器对象的`throw`方法抛出的，而不是用`throw`命令抛出的。后者只能被函数体外的`catch`语句捕获。


如果 Generator 函数内部没有部署`try...catch`代码块，那么`throw`方法抛出的错误，将被外部`try...catch`代码块捕获。

如果 Generator 函数内部和外部，都没有部署`try...catch`代码块，那么程序将报错，直接中断执行。

`throw`方法抛出的错误要被内部捕获，前提是必须至少执行过一次`next`方法。

`throw`方法被内部捕获以后，会附带执行到下一条`yield`表达式，这种情况下等同于执行一次`next`方法。

另外，`throw`命令与`g.throw`方法是无关的，两者互不影响。



这种函数体内捕获错误的机制，大大方便了对错误的处理。多个`yield`表达式，可以只用一个`try...catch`代码块来捕获错误。如果使用回调函数的写法，想要捕获多个错误，就不得不为每个函数内部写一个错误处理语句，现在只在 Generator 函数内部写一次`catch`语句就可以了。

Generator 函数体外抛出的错误，可以在函数体内捕获；反过来，Generator 函数体内抛出的错误，也可以被函数体外的`catch`捕获。

一旦 Generator 执行过程中抛出错误，且没有被内部捕获，就不会再执行下去了。如果此后还调用`next`方法，将返回一个`value`属性等于`undefined`、`done`属性等于`true`的对象，即 JavaScript 引擎认为这个 Generator 已经运行结束了。

### Generator.prototype.return()

Generator 函数返回的遍历器对象，还有一个`return()`方法，可以返回给定的值，并且终结遍历 Generator 函数。

如果`return()`方法调用时，不提供参数，则返回值的`value`属性为`undefined`。

如果 Generator 函数内部有`try...finally`代码块，且正在执行`try`代码块，那么`return()`方法会导致立刻进入`finally`代码块，执行完以后，整个函数才会结束。



### next()、throw()、return() 的共同点

`next()`、`throw()`、`return()`这三个方法本质上是同一件事，可以放在一起理解。它们的作用都是让 Generator 函数恢复执行，并且使用不同的语句替换`yield`表达式。

`next()`是将`yield`表达式替换成一个值。

`throw()`是将`yield`表达式替换成一个`throw`语句。

`return()`是将`yield`表达式替换成一个`return`语句。


### 应用

异步操作的同步化表达

控制流管理


部署 Iterator 接口

作为数据结构

## async 函数

ES2017 标准引入了 async 函数，使得异步操作变得更加方便。

async 函数是什么？一句话，它就是 Generator 函数的语法糖。

```
const fs = require('fs');

const readFile = function (fileName) {
  return new Promise(function (resolve, reject) {
    fs.readFile(fileName, function(error, data) {
      if (error) return reject(error);
      resolve(data);
    });
  });
};

const gen = function* () {
  const f1 = yield readFile('/etc/fstab');
  const f2 = yield readFile('/etc/shells');
  console.log(f1.toString());
  console.log(f2.toString());
};
```

上面代码的函数`gen`可以写成`async`函数，就是下面这样。

```
const asyncReadFile = async function () {
  const f1 = await readFile('/etc/fstab');
  const f2 = await readFile('/etc/shells');
  console.log(f1.toString());
  console.log(f2.toString());
};
```

一比较就会发现，`async`函数就是将 Generator 函数的星号（`*`）替换成`async`，将`yield`替换成`await`，仅此而已。

`async`函数对 Generator 函数的改进，体现在以下四点。

（1）内置执行器。

Generator 函数的执行必须靠执行器，所以才有了`co`模块，而`async`函数自带执行器。也就是说，`async`函数的执行，与普通函数一模一样，只要一行。

```
asyncReadFile();
```

上面的代码调用了`asyncReadFile`函数，然后它就会自动执行，输出最后结果。这完全不像 Generator 函数，需要调用`next`方法，或者用`co`模块，才能真正执行，得到最后结果。

（2）更好的语义。

`async`和`await`，比起星号和`yield`，语义更清楚了。`async`表示函数里有异步操作，`await`表示紧跟在后面的表达式需要等待结果。

（3）更广的适用性。

`co`模块约定，`yield`命令后面只能是 Thunk 函数或 Promise 对象，而`async`函数的`await`命令后面，可以是 Promise 对象和原始类型的值（数值、字符串和布尔值，但这时会自动转成立即 resolved 的 Promise 对象）。

（4）返回值是 Promise。

`async`函数的返回值是 Promise 对象，这比 Generator 函数的返回值是 Iterator 对象方便多了。你可以用`then`方法指定下一步的操作。

进一步说，`async`函数完全可以看作多个异步操作，包装成的一个 Promise 对象，而`await`命令就是内部`then`命令的语法糖。

### 基本用法

`async`函数返回一个 Promise 对象，可以使用`then`方法添加回调函数。当函数执行的时候，一旦遇到`await`就会先返回，等到异步操作完成，再接着执行函数体内后面的语句。

下面是一个例子。

```
async function getStockPriceByName(name) {
  const symbol = await getStockSymbol(name);
  const stockPrice = await getStockPrice(symbol);
  return stockPrice;
}

getStockPriceByName('goog').then(function (result) {
  console.log(result);
});
```

上面代码是一个获取股票报价的函数，函数前面的`async`关键字，表明该函数内部有异步操作。调用该函数时，会立即返回一个`Promise`对象。

由于`async`函数返回的是 Promise 对象，可以作为`await`命令的参数。所以，上面的例子也可以写成下面的形式。

```
async function timeout(ms) {
  await new Promise((resolve) => {
    setTimeout(resolve, ms);
  });
}

async function asyncPrint(value, ms) {
  await timeout(ms);
  console.log(value);
}

asyncPrint('hello world', 50);
```

async 函数有多种使用形式。

```
// 函数声明
async function foo() {}

// 函数表达式
const foo = async function () {};

// 对象的方法
let obj = { async foo() {} };
obj.foo().then(...)

// Class 的方法
class Storage {
  constructor() {
    this.cachePromise = caches.open('avatars');
  }

  async getAvatar(name) {
    const cache = await this.cachePromise;
    return cache.match(`/avatars/${name}.jpg`);
  }
}

const storage = new Storage();
storage.getAvatar('jake').then(…);

// 箭头函数
const foo = async () => {};
```

### 语法

`async`函数的语法规则总体上比较简单，难点是错误处理机制。

### 返回 Promise 对象

`async`函数返回一个 Promise 对象。

`async`函数内部`return`语句返回的值，会成为`then`方法回调函数的参数。

```
async function f() {
  return 'hello world';
}

f().then(v => console.log(v))
// "hello world"
```

`async`函数内部抛出错误，会导致返回的 Promise 对象变为`reject`状态。抛出的错误对象会被`catch`方法回调函数接收到。

```
async function f() {
  throw new Error('出错了');
}

f().then(
  v => console.log('resolve', v),
  e => console.log('reject', e)
)
//reject Error: 出错了
```

### Promise 对象的状态变化

`async`函数返回的 Promise 对象，必须等到内部所有`await`命令后面的 Promise 对象执行完，才会发生状态改变，除非遇到`return`语句或者抛出错误。也就是说，只有`async`函数内部的异步操作执行完，才会执行`then`方法指定的回调函数。

下面是一个例子。

```
async function getTitle(url) {
  let response = await fetch(url);
  let html = await response.text();
  return html.match(/<title>([\s\S]+)<\/title>/i)[1];
}
getTitle('https://tc39.github.io/ecma262/').then(console.log)
// "ECMAScript 2017 Language Specification"
```

上面代码中，函数`getTitle`内部有三个操作：抓取网页、取出文本、匹配页面标题。只有这三个操作全部完成，才会执行`then`方法里面的`console.log`。

### await 命令

正常情况下，`await`命令后面是一个 Promise 对象，返回该对象的结果。如果不是 Promise 对象，就直接返回对应的值。

```
async function f() {
  // 等同于
  // return 123;
  return await 123;
}

f().then(v => console.log(v))
// 123
```

上面代码中，`await`命令的参数是数值`123`，这时等同于`return 123`。

另一种情况是，`await`命令后面是一个`thenable`对象（即定义了`then`方法的对象），那么`await`会将其等同于 Promise 对象。

```
class Sleep {
  constructor(timeout) {
    this.timeout = timeout;
  }
  then(resolve, reject) {
    const startTime = Date.now();
    setTimeout(
      () => resolve(Date.now() - startTime),
      this.timeout
    );
  }
}

(async () => {
  const sleepTime = await new Sleep(1000);
  console.log(sleepTime);
})();
// 1000
```

上面代码中，`await`命令后面是一个`Sleep`对象的实例。这个实例不是 Promise 对象，但是因为定义了`then`方法，`await`会将其视为`Promise`处理。

这个例子还演示了如何实现休眠效果。JavaScript 一直没有休眠的语法，但是借助`await`命令就可以让程序停顿指定的时间。下面给出了一个简化的`sleep`实现。

```
function sleep(interval) {
  return new Promise(resolve => {
    setTimeout(resolve, interval);
  })
}

// 用法
async function one2FiveInAsync() {
  for(let i = 1; i <= 5; i++) {
    console.log(i);
    await sleep(1000);
  }
}

one2FiveInAsync();
```

`await`命令后面的 Promise 对象如果变为`reject`状态，则`reject`的参数会被`catch`方法的回调函数接收到。

```
async function f() {
  await Promise.reject('出错了');
}

f()
.then(v => console.log(v))
.catch(e => console.log(e))
// 出错了
```

注意，上面代码中，`await`语句前面没有`return`，但是`reject`方法的参数依然传入了`catch`方法的回调函数。这里如果在`await`前面加上`return`，效果是一样的。

任何一个`await`语句后面的 Promise 对象变为`reject`状态，那么整个`async`函数都会中断执行。

```
async function f() {
  await Promise.reject('出错了');
  await Promise.resolve('hello world'); // 不会执行
}
```

上面代码中，第二个`await`语句是不会执行的，因为第一个`await`语句状态变成了`reject`。

有时，我们希望即使前一个异步操作失败，也不要中断后面的异步操作。这时可以将第一个`await`放在`try...catch`结构里面，这样不管这个异步操作是否成功，第二个`await`都会执行。

```
async function f() {
  try {
    await Promise.reject('出错了');
  } catch(e) {
  }
  return await Promise.resolve('hello world');
}

f()
.then(v => console.log(v))
// hello world
```

另一种方法是`await`后面的 Promise 对象再跟一个`catch`方法，处理前面可能出现的错误。

```
async function f() {
  await Promise.reject('出错了')
    .catch(e => console.log(e));
  return await Promise.resolve('hello world');
}

f()
.then(v => console.log(v))
// 出错了
// hello world
```

## 错误处理

如果`await`后面的异步操作出错，那么等同于`async`函数返回的 Promise 对象被`reject`。

```
async function f() {
  await new Promise(function (resolve, reject) {
    throw new Error('出错了');
  });
}

f()
.then(v => console.log(v))
.catch(e => console.log(e))
// Error：出错了
```

上面代码中，`async`函数`f`执行后，`await`后面的 Promise 对象会抛出一个错误对象，导致`catch`方法的回调函数被调用，它的参数就是抛出的错误对象。具体的执行机制，可以参考后文的“async 函数的实现原理”。

防止出错的方法，也是将其放在`try...catch`代码块之中。

```
async function f() {
  try {
    await new Promise(function (resolve, reject) {
      throw new Error('出错了');
    });
  } catch(e) {
  }
  return await('hello world');
}
```

如果有多个`await`命令，可以统一放在`try...catch`结构中。

```
async function main() {
  try {
    const val1 = await firstStep();
    const val2 = await secondStep(val1);
    const val3 = await thirdStep(val1, val2);

    console.log('Final: ', val3);
  }
  catch (err) {
    console.error(err);
  }
}
```

下面的例子使用`try...catch`结构，实现多次重复尝试。

```
const superagent = require('superagent');
const NUM_RETRIES = 3;

async function test() {
  let i;
  for (i = 0; i < NUM_RETRIES; ++i) {
    try {
      await superagent.get('http://google.com/this-throws-an-error');
      break;
    } catch(err) {}
  }
  console.log(i); // 3
}

test();
```

上面代码中，如果`await`操作成功，就会使用`break`语句退出循环；如果失败，会被`catch`语句捕捉，然后进入下一轮循环。

## 使用注意点

第一点，前面已经说过，`await`命令后面的`Promise`对象，运行结果可能是`rejected`，所以最好把`await`命令放在`try...catch`代码块中。

```
async function myFunction() {
  try {
    await somethingThatReturnsAPromise();
  } catch (err) {
    console.log(err);
  }
}

// 另一种写法

async function myFunction() {
  await somethingThatReturnsAPromise()
  .catch(function (err) {
    console.log(err);
  });
}
```

第二点，多个`await`命令后面的异步操作，如果不存在继发关系，最好让它们同时触发。

```
let foo = await getFoo();
let bar = await getBar();
```

上面代码中，`getFoo`和`getBar`是两个独立的异步操作（即互不依赖），被写成继发关系。这样比较耗时，因为只有`getFoo`完成以后，才会执行`getBar`，完全可以让它们同时触发。

```
// 写法一
let [foo, bar] = await Promise.all([getFoo(), getBar()]);

// 写法二
let fooPromise = getFoo();
let barPromise = getBar();
let foo = await fooPromise;
let bar = await barPromise;
```

上面两种写法，`getFoo`和`getBar`都是同时触发，这样就会缩短程序的执行时间。

第三点，`await`命令只能用在`async`函数之中，如果用在普通函数，就会报错。

```
async function dbFuc(db) {
  let docs = [{}, {}, {}];

  // 报错
  docs.forEach(function (doc) {
    await db.post(doc);
  });
}
```

上面代码会报错，因为`await`用在普通函数之中了。但是，如果将`forEach`方法的参数改成`async`函数，也有问题。

```
function dbFuc(db) { //这里不需要 async
  let docs = [{}, {}, {}];

  // 可能得到错误结果
  docs.forEach(async function (doc) {
    await db.post(doc);
  });
}
```

上面代码可能不会正常工作，原因是这时三个`db.post()`操作将是并发执行，也就是同时执行，而不是继发执行。正确的写法是采用`for`循环。

```
async function dbFuc(db) {
  let docs = [{}, {}, {}];

  for (let doc of docs) {
    await db.post(doc);
  }
}
```

另一种方法是使用数组的`reduce()`方法。

```
async function dbFuc(db) {
  let docs = [{}, {}, {}];

  await docs.reduce(async (_, doc) => {
    await _;
    await db.post(doc);
  }, undefined);
}
```

上面例子中，`reduce()`方法的第一个参数是`async`函数，导致该函数的第一个参数是前一步操作返回的 Promise 对象，所以必须使用`await`等待它操作结束。另外，`reduce()`方法返回的是`docs`数组最后一个成员的`async`函数的执行结果，也是一个 Promise 对象，导致在它前面也必须加上`await`。

上面的`reduce()`的参数函数里面没有`return`语句，原因是这个函数的主要目的是`db.post()`操作，不是返回值。而且`async`函数不管有没有`return`语句，总是返回一个 Promise 对象，所以这里的`return`是不必要的。

如果确实希望多个请求并发执行，可以使用`Promise.all`方法。当三个请求都会`resolved`时，下面两种写法效果相同。

```
async function dbFuc(db) {
  let docs = [{}, {}, {}];
  let promises = docs.map((doc) => db.post(doc));

  let results = await Promise.all(promises);
  console.log(results);
}

// 或者使用下面的写法

async function dbFuc(db) {
  let docs = [{}, {}, {}];
  let promises = docs.map((doc) => db.post(doc));

  let results = [];
  for (let promise of promises) {
    results.push(await promise);
  }
  console.log(results);
}
```

第四点，async 函数可以保留运行堆栈。

```
const a = () => {
  b().then(() => c());
};
```

上面代码中，函数`a`内部运行了一个异步任务`b()`。当`b()`运行的时候，函数`a()`不会中断，而是继续执行。等到`b()`运行结束，可能`a()`早就运行结束了，`b()`所在的上下文环境已经消失了。如果`b()`或`c()`报错，错误堆栈将不包括`a()`。

现在将这个例子改成`async`函数。

```
const a = async () => {
  await b();
  c();
};
```

上面代码中，`b()`运行的时候，`a()`是暂停执行，上下文环境都保存着。一旦`b()`或`c()`报错，错误堆栈将包括`a()`。



## 与其他异步处理方法的比较

我们通过一个例子，来看 async 函数与 Promise、Generator 函数的比较。

假定某个 DOM 元素上面，部署了一系列的动画，前一个动画结束，才能开始后一个。如果当中有一个动画出错，就不再往下执行，返回上一个成功执行的动画的返回值。

首先是 Promise 的写法。

```
function chainAnimationsPromise(elem, animations) {

  // 变量ret用来保存上一个动画的返回值
  let ret = null;

  // 新建一个空的Promise
  let p = Promise.resolve();

  // 使用then方法，添加所有动画
  for(let anim of animations) {
    p = p.then(function(val) {
      ret = val;
      return anim(elem);
    });
  }

  // 返回一个部署了错误捕捉机制的Promise
  return p.catch(function(e) {
    /* 忽略错误，继续执行 */
  }).then(function() {
    return ret;
  });

}
```

虽然 Promise 的写法比回调函数的写法大大改进，但是一眼看上去，代码完全都是 Promise 的 API（`then`、`catch`等等），操作本身的语义反而不容易看出来。

接着是 Generator 函数的写法。

```
function chainAnimationsGenerator(elem, animations) {

  return spawn(function*() {
    let ret = null;
    try {
      for(let anim of animations) {
        ret = yield anim(elem);
      }
    } catch(e) {
      /* 忽略错误，继续执行 */
    }
    return ret;
  });

}
```

上面代码使用 Generator 函数遍历了每个动画，语义比 Promise 写法更清晰，用户定义的操作全部都出现在`spawn`函数的内部。这个写法的问题在于，必须有一个任务运行器，自动执行 Generator 函数，上面代码的`spawn`函数就是自动执行器，它返回一个 Promise 对象，而且必须保证`yield`语句后面的表达式，必须返回一个 Promise。

最后是 async 函数的写法。

```
async function chainAnimationsAsync(elem, animations) {
  let ret = null;
  try {
    for(let anim of animations) {
      ret = await anim(elem);
    }
  } catch(e) {
    /* 忽略错误，继续执行 */
  }
  return ret;
}
```

可以看到 Async 函数的实现最简洁，最符合语义，几乎没有语义不相关的代码。它将 Generator 写法中的自动执行器，改在语言层面提供，不暴露给用户，因此代码量最少。如果使用 Generator 写法，自动执行器需要用户自己提供。



[Promise、Generator、Async有什么区别？ - 掘金 (juejin.cn)](https://juejin.cn/post/7062155174436929550)